Workbook
Name Accounts: Lists!$B$3:$B$13
Name ExpenditureCat: Lists!$B$29:$B$41
Name Income: 'Montly Expenses'!$B$3:$F$6
Name Invested: Table2[#All]
Name OtherExpenditureCat: Lists!$B$16:$B$26
Name Slicer_Account: #N/A
Name Test_outgoing: WEEKLY!#REF!
Name Test_outgoing: #REF!

Sheet Net Worth Dashboard
A40: Tables
A42: Sum of Amount | B42: Column Labels | L42: Sum of Amount | M42: Column Labels
A43: Row Labels | B43: Credit | C43: Crypto | D43: Debit (Revolut) | E43: Monzo (Savings) | F43: Monzo (Spend) | G43: Moneybox (LISA) | H43: S&S ISA | I43: Chase | J43: Grand Total | L43: Row Labels | M43: Credit | N43: Crypto | O43: Debit (Revolut) | P43: Monzo (Savings) | Q43: Monzo (Spend) | R43: Moneybox (LISA) | S43: S&S ISA | T43: Chase | U43: Grand Total
A44: 45654 | B44: -675 | C44: 2568 | D44: 167 | E44: 2204 | F44: 3076 | G44: 9943 | H44: 5229 | J44: 22512 | L44: 45654 | M44: -675 | N44: 2568 | O44: 167 | P44: 2204 | Q44: 3076 | R44: 9943 | S44: 5229 | U44: 22512
A45: 45656 | B45: -575 | C45: 2668 | D45: 267 | E45: 2304 | F45: 3176 | G45: 10043 | H45: 5329 | J45: 23212 | L45: 45656 | M45: -575 | N45: 2668 | O45: 267 | P45: 2304 | Q45: 3176 | R45: 10043 | S45: 5329 | U45: 23212
A46: 45718 | B46: 0 | C46: 2105 | D46: 20 | E46: 426 | F46: 1472 | G46: 13883 | H46: 5331.77 | J46: 23237.77 | L46: 45718 | M46: 0 | N46: 2105 | O46: 20 | P46: 426 | Q46: 1472 | R46: 13883 | S46: 5331.77 | U46: 23237.77
A47: 45749 | B47: 0 | C47: 2271.64 | D47: 7 | E47: 4832.23 | F47: 1897.69 | G47: 14924.24 | H47: 0 | J47: 23932.8 | L47: 45749 | M47: 0 | N47: 2271.64 | O47: 7 | P47: 4832.23 | Q47: 1897.69 | R47: 14924.24 | S47: 0 | U47: 23932.8
A48: 45791 | B48: -408.77 | C48: 2152 | D48: 1.92 | E48: 635 | F48: 1147.88 | G48: 15234 | H48: 4274.6 | J48: 23036.63 | L48: 45791 | M48: -408.77 | N48: 2152 | O48: 1.92 | P48: 635 | Q48: 1147.88 | R48: 15234 | S48: 4274.6 | U48: 23036.63
A49: 45808 | B49: 0 | C49: 2000 | D49: 45 | E49: 1135 | F49: 1500 | G49: 15259 | H49: 4254 | J49: 24193 | L49: 45808 | M49: 0 | N49: 2000 | O49: 45 | P49: 1135 | Q49: 1500 | R49: 15259 | S49: 4254 | U49: 24193
A50: 45839 | B50: 339 | C50: 1890 | D50: 50 | E50: 1742 | F50: 1193 | G50: 15301 | H50: 4370 | J50: 24885 | L50: 45839 | M50: 339 | N50: 1890 | O50: 50 | P50: 1742 | Q50: 1193 | R50: 15301 | S50: 4370 | U50: 24885
A51: 45872 | B51: 0 | C51: 2250 | D51: 50 | E51: 2798 | F51: 983 | G51: 15346 | H51: 4525 | J51: 25952 | L51: 45872 | M51: 0 | N51: 2250 | O51: 50 | P51: 2798 | Q51: 983 | R51: 15346 | S51: 4525 | U51: 25952
A52: 45962 | B52: 0 | C52: 2225.01 | D52: 120 | E52: 4205 | F52: 969 | G52: 15462 | H52: 5022 | J52: 28003.01 | L52: 45962 | M52: 0 | N52: 2225.01 | O52: 120 | P52: 4205 | Q52: 969 | R52: 15462 | S52: 5022 | U52: 28003.01
A53: 46000 | B53: 110 | C53: 1741 | D53: 169 | E53: 4024 | F53: 1070 | G53: 15511 | H53: 4976.05 | J53: 27601.05 | L53: 46000 | M53: 110 | N53: 1741 | O53: 169 | P53: 4024 | Q53: 1070 | R53: 15511 | S53: 4976.05 | U53: 27601.05
A54: 46021 | B54: 0 | C54: 1700 | D54: 194 | E54: 4824 | F54: 1720 | G54: 15538 | H54: 4972 | J54: 28948 | L54: 46021 | M54: 0 | N54: 1700 | O54: 194 | P54: 4824 | Q54: 1720 | R54: 15538 | S54: 4972 | U54: 28948
A55: 46063 | B55: 0 | C55: 1500 | D55: 230 | E55: 3607 | F55: 451 | G55: 15733 | H55: 5087 | J55: 26608 | L55: 46063 | M55: 0 | N55: 1500 | O55: 230 | P55: 3607 | Q55: 451 | R55: 15733 | S55: 5087 | U55: 26608
A56: 46118 | B56: 0 | C56: 1267 | D56: 230 | E56: 596.6 | F56: 978.18 | G56: 15800 | H56: 4961 | I56: 2055.45 | J56: 25888.23 | L56: 46118 | M56: 0 | N56: 1267 | O56: 230 | P56: 596.6 | Q56: 978.18 | R56: 15800 | S56: 4961 | T56: 2055.45 | U56: 25888.23
A57: 46157 | B57: 0 | C57: 1500 | D57: 230 | E57: 597 | F57: 1045 | G57: 15850 | H57: 5482 | I57: 2062 | J57: 26766 | L57: 46157 | M57: 0 | N57: 1500 | O57: 230 | P57: 597 | Q57: 1045 | R57: 15850 | S57: 5482 | T57: 2062 | U57: 26766
A58: 46177 | B58: 0 | C58: 1200 | D58: 216 | E58: 1400 | F58: 621 | G58: 15892 | H58: 5574 | I58: 17190 | J58: 42093 | L58: 46177 | M58: 0 | N58: 1200 | O58: 216 | P58: 1400 | Q58: 621 | R58: 15892 | S58: 5574 | T58: 17190 | U58: 42093
A59: Grand Total | B59: -1209.77 | C59: 29037.65 | D59: 1996.92 | E59: 35329.83 | F59: 21299.75 | G59: 219719.24 | H59: 69387.42 | I59: 21307.45 | J59: 396868.49 | L59: Grand Total | M59: -1209.77 | N59: 29037.65 | O59: 1996.92 | P59: 35329.83 | Q59: 21299.75 | R59: 219719.24 | S59: 69387.42 | T59: 21307.45 | U59: 396868.49

Sheet Net Worth Input
A1: Invested
A2: Account | B2: Invested | C2: Withdrawn | D2: Value
A3: Moneybox (LISA) | B3: 12000
A4: S&S ISA | B4: 4000
A5: Crypto | B5: 4025 | C5: 2643
A6: Monzo (Savings) | B6: 0 | C6: 0
A7: Chase | B7: 17000
A10: Reports - Breakdown
A11: Date | B11: Account | C11: Amount | D11: P/L | E11: PL (%) | F11: Notes
A12: 46177 | B12: Chase | C12: 17190 | D12: =Table1[[#This Row],[Amount]]-INDEX(Table2[], MATCH(Table1[[#This Row],[Account]],Table2[Account],0), 2) + INDEX(Table2[], MATCH(Table1[[#This Row],[Account]],Table2[Account],0), 3) -> 190 | E12: =Table1[[#This Row],[P/L]]/INDEX(Table2[], MATCH(Table1[[#This Row],[Account]], Table2[Account],0),2) -> 0.011176471
A13: 46177 | B13: Moneybox (LISA) | C13: 15892 | D13: =Table1[[#This Row],[Amount]]-INDEX(Table2[], MATCH(Table1[[#This Row],[Account]],Table2[Account],0), 2) + INDEX(Table2[], MATCH(Table1[[#This Row],[Account]],Table2[Account],0), 3) -> 3892 | E13: =Table1[[#This Row],[P/L]]/INDEX(Table2[], MATCH(Table1[[#This Row],[Account]], Table2[Account],0),2) -> 0.32433333
A14: 46177 | B14: S&S ISA | C14: 5574 | D14: =Table1[[#This Row],[Amount]]-INDEX(Table2[], MATCH(Table1[[#This Row],[Account]],Table2[Account],0), 2) + INDEX(Table2[], MATCH(Table1[[#This Row],[Account]],Table2[Account],0), 3) -> 1574 | E14: =Table1[[#This Row],[P/L]]/INDEX(Table2[], MATCH(Table1[[#This Row],[Account]], Table2[Account],0),2) -> 0.3935
A15: 46177 | B15: Crypto | C15: 1200 | D15: =Table1[[#This Row],[Amount]]-INDEX(Table2[], MATCH(Table1[[#This Row],[Account]],Table2[Account],0), 2) + INDEX(Table2[], MATCH(Table1[[#This Row],[Account]],Table2[Account],0), 3) -> -182 | E15: =Table1[[#This Row],[P/L]]/INDEX(Table2[], MATCH(Table1[[#This Row],[Account]], Table2[Account],0),2) -> -0.045217391
A16: 46177 | B16: Monzo (Spend) | C16: 621 | D16: =Table1[[#This Row],[Amount]]-INDEX(Table2[], MATCH(Table1[[#This Row],[Account]],Table2[Account],0), 2) + INDEX(Table2[], MATCH(Table1[[#This Row],[Account]],Table2[Account],0), 3) -> #N/A | E16: =Table1[[#This Row],[P/L]]/INDEX(Table2[], MATCH(Table1[[#This Row],[Account]], Table2[Account],0),2) -> #N/A
A17: 46177 | B17: Debit (Revolut) | C17: 216 | D17: =Table1[[#This Row],[Amount]]-INDEX(Table2[], MATCH(Table1[[#This Row],[Account]],Table2[Account],0), 2) + INDEX(Table2[], MATCH(Table1[[#This Row],[Account]],Table2[Account],0), 3) -> #N/A | E17: =Table1[[#This Row],[P/L]]/INDEX(Table2[], MATCH(Table1[[#This Row],[Account]], Table2[Account],0),2) -> #N/A
A18: 46177 | B18: Credit | C18: 0 | D18: =Table1[[#This Row],[Amount]]-INDEX(Table2[], MATCH(Table1[[#This Row],[Account]],Table2[Account],0), 2) + INDEX(Table2[], MATCH(Table1[[#This Row],[Account]],Table2[Account],0), 3) -> #N/A | E18: =Table1[[#This Row],[P/L]]/INDEX(Table2[], MATCH(Table1[[#This Row],[Account]], Table2[Account],0),2) -> #N/A
A19: 46177 | B19: Monzo (Savings) | C19: 1400 | D19: =Table1[[#This Row],[Amount]]-INDEX(Table2[], MATCH(Table1[[#This Row],[Account]],Table2[Account],0), 2) + INDEX(Table2[], MATCH(Table1[[#This Row],[Account]],Table2[Account],0), 3) -> 1400 | E19: =Table1[[#This Row],[P/L]]/INDEX(Table2[], MATCH(Table1[[#This Row],[Account]], Table2[Account],0),2) -> #DIV/0!
A20: 46157 | B20: Chase | C20: 2062 | D20: =Table1[[#This Row],[Amount]]-INDEX(Table2[], MATCH(Table1[[#This Row],[Account]],Table2[Account],0), 2) + INDEX(Table2[], MATCH(Table1[[#This Row],[Account]],Table2[Account],0), 3) -> -14938 | E20: =Table1[[#This Row],[P/L]]/INDEX(Table2[], MATCH(Table1[[#This Row],[Account]], Table2[Account],0),2) -> -0.87870588
A21: 46157 | B21: Moneybox (LISA) | C21: 15850 | D21: =Table1[[#This Row],[Amount]]-INDEX(Table2[], MATCH(Table1[[#This Row],[Account]],Table2[Account],0), 2) + INDEX(Table2[], MATCH(Table1[[#This Row],[Account]],Table2[Account],0), 3) -> 3850 | E21: =Table1[[#This Row],[P/L]]/INDEX(Table2[], MATCH(Table1[[#This Row],[Account]], Table2[Account],0),2) -> 0.32083333
A22: 46157 | B22: S&S ISA | C22: 5482 | D22: =Table1[[#This Row],[Amount]]-INDEX(Table2[], MATCH(Table1[[#This Row],[Account]],Table2[Account],0), 2) + INDEX(Table2[], MATCH(Table1[[#This Row],[Account]],Table2[Account],0), 3) -> 1482 | E22: =Table1[[#This Row],[P/L]]/INDEX(Table2[], MATCH(Table1[[#This Row],[Account]], Table2[Account],0),2) -> 0.3705
A23: 46157 | B23: Crypto | C23: 1500 | D23: =Table1[[#This Row],[Amount]]-INDEX(Table2[], MATCH(Table1[[#This Row],[Account]],Table2[Account],0), 2) + INDEX(Table2[], MATCH(Table1[[#This Row],[Account]],Table2[Account],0), 3) -> 118 | E23: =Table1[[#This Row],[P/L]]/INDEX(Table2[], MATCH(Table1[[#This Row],[Account]], Table2[Account],0),2) -> 0.02931677
... A87: 45791 | B87: Crypto | C87: 2152 | D87: =Table1[[#This Row],[Amount]]-INDEX(Table2[], MATCH(Table1[[#This Row],[Account]],Table2[Account],0), 2) + INDEX(Table2[], MATCH(Table1[[#This Row],[Account]],Table2[Account],0), 3) -> 770 | E87: =Table1[[#This Row],[P/L]]/INDEX(Table2[], MATCH(Table1[[#This Row],[Account]], Table2[Account],0),2) -> 0.19130435
A88: 45791 | B88: Monzo (Spend) | C88: =739.11+408.77 -> 1147.88 | D88: =Table1[[#This Row],[Amount]]-INDEX(Table2[], MATCH(Table1[[#This Row],[Account]],Table2[Account],0), 2) + INDEX(Table2[], MATCH(Table1[[#This Row],[Account]],Table2[Account],0), 3) -> #N/A | E88: =Table1[[#This Row],[P/L]]/INDEX(Table2[], MATCH(Table1[[#This Row],[Account]], Table2[Account],0),2) -> #N/A
A89: 45791 | B89: Debit (Revolut) | C89: 1.92 | D89: =Table1[[#This Row],[Amount]]-INDEX(Table2[], MATCH(Table1[[#This Row],[Account]],Table2[Account],0), 2) + INDEX(Table2[], MATCH(Table1[[#This Row],[Account]],Table2[Account],0), 3) -> #N/A | E89: =Table1[[#This Row],[P/L]]/INDEX(Table2[], MATCH(Table1[[#This Row],[Account]], Table2[Account],0),2) -> #N/A
A90: 45791 | B90: Credit | C90: -408.77 | D90: =Table1[[#This Row],[Amount]]-INDEX(Table2[], MATCH(Table1[[#This Row],[Account]],Table2[Account],0), 2) + INDEX(Table2[], MATCH(Table1[[#This Row],[Account]],Table2[Account],0), 3) -> #N/A | E90: =Table1[[#This Row],[P/L]]/INDEX(Table2[], MATCH(Table1[[#This Row],[Account]], Table2[Account],0),2) -> #N/A
A91: 45791 | B91: Monzo (Savings) | C91: 635 | D91: =Table1[[#This Row],[Amount]]-INDEX(Table2[], MATCH(Table1[[#This Row],[Account]],Table2[Account],0), 2) + INDEX(Table2[], MATCH(Table1[[#This Row],[Account]],Table2[Account],0), 3) -> 635 | E91: =Table1[[#This Row],[P/L]]/INDEX(Table2[], MATCH(Table1[[#This Row],[Account]], Table2[Account],0),2) -> #DIV/0!
A92: 45749 | B92: Moneybox (LISA) | C92: 14924.24 | D92: =Table1[[#This Row],[Amount]]-INDEX(Table2[], MATCH(Table1[[#This Row],[Account]],Table2[Account],0), 2) + INDEX(Table2[], MATCH(Table1[[#This Row],[Account]],Table2[Account],0), 3) -> 2924.24 | E92: =Table1[[#This Row],[P/L]]/INDEX(Table2[], MATCH(Table1[[#This Row],[Account]], Table2[Account],0),2) -> 0.24368667
A93: 45749 | B93: S&S ISA | C93: 0 | D93: =Table1[[#This Row],[Amount]]-INDEX(Table2[], MATCH(Table1[[#This Row],[Account]],Table2[Account],0), 2) + INDEX(Table2[], MATCH(Table1[[#This Row],[Account]],Table2[Account],0), 3) -> -4000 | E93: =Table1[[#This Row],[P/L]]/INDEX(Table2[], MATCH(Table1[[#This Row],[Account]], Table2[Account],0),2) -> -1
A94: 45749 | B94: Crypto | C94: 2271.64 | D94: =Table1[[#This Row],[Amount]]-INDEX(Table2[], MATCH(Table1[[#This Row],[Account]],Table2[Account],0), 2) + INDEX(Table2[], MATCH(Table1[[#This Row],[Account]],Table2[Account],0), 3) -> 889.64 | E94: =Table1[[#This Row],[P/L]]/INDEX(Table2[], MATCH(Table1[[#This Row],[Account]], Table2[Account],0),2) -> 0.22102857
A95: 45749 | B95: Monzo (Spend) | C95: 1897.69 | D95: =Table1[[#This Row],[Amount]]-INDEX(Table2[], MATCH(Table1[[#This Row],[Account]],Table2[Account],0), 2) + INDEX(Table2[], MATCH(Table1[[#This Row],[Account]],Table2[Account],0), 3) -> #N/A | E95: =Table1[[#This Row],[P/L]]/INDEX(Table2[], MATCH(Table1[[#This Row],[Account]], Table2[Account],0),2) -> #N/A
A96: 45749 | B96: Debit (Revolut) | C96: 7 | D96: =Table1[[#This Row],[Amount]]-INDEX(Table2[], MATCH(Table1[[#This Row],[Account]],Table2[Account],0), 2) + INDEX(Table2[], MATCH(Table1[[#This Row],[Account]],Table2[Account],0), 3) -> #N/A | E96: =Table1[[#This Row],[P/L]]/INDEX(Table2[], MATCH(Table1[[#This Row],[Account]], Table2[Account],0),2) -> #N/A
A97: 45749 | B97: Credit | C97: 0 | D97: =Table1[[#This Row],[Amount]]-INDEX(Table2[], MATCH(Table1[[#This Row],[Account]],Table2[Account],0), 2) + INDEX(Table2[], MATCH(Table1[[#This Row],[Account]],Table2[Account],0), 3) -> #N/A | E97: =Table1[[#This Row],[P/L]]/INDEX(Table2[], MATCH(Table1[[#This Row],[Account]], Table2[Account],0),2) -> #N/A
A98: 45749 | B98: Monzo (Savings) | C98: 4832.23 | D98: =Table1[[#This Row],[Amount]]-INDEX(Table2[], MATCH(Table1[[#This Row],[Account]],Table2[Account],0), 2) + INDEX(Table2[], MATCH(Table1[[#This Row],[Account]],Table2[Account],0), 3) -> 4832.23 | E98: =Table1[[#This Row],[P/L]]/INDEX(Table2[], MATCH(Table1[[#This Row],[Account]], Table2[Account],0),2) -> #DIV/0!
A99: 45718 | B99: Moneybox (LISA) | C99: =13133+750 -> 13883 | D99: =Table1[[#This Row],[Amount]]-INDEX(Table2[], MATCH(Table1[[#This Row],[Account]],Table2[Account],0), 2) + INDEX(Table2[], MATCH(Table1[[#This Row],[Account]],Table2[Account],0), 3) -> 1883 | E99: =Table1[[#This Row],[P/L]]/INDEX(Table2[], MATCH(Table1[[#This Row],[Account]], Table2[Account],0),2) -> 0.15691667 | F99: LISA Switched to Moneybox
A100: 45718 | B100: S&S ISA | C100: 5331.77 | D100: =Table1[[#This Row],[Amount]]-INDEX(Table2[], MATCH(Table1[[#This Row],[Account]],Table2[Account],0), 2) + INDEX(Table2[], MATCH(Table1[[#This Row],[Account]],Table2[Account],0), 3) -> 1331.77 | E100: =Table1[[#This Row],[P/L]]/INDEX(Table2[], MATCH(Table1[[#This Row],[Account]], Table2[Account],0),2) -> 0.3329425 | F100: S&S ISA switched to T212
A101: 45718 | B101: Crypto | C101: 2105 | D101: =Table1[[#This Row],[Amount]]-INDEX(Table2[], MATCH(Table1[[#This Row],[Account]],Table2[Account],0), 2) + INDEX(Table2[], MATCH(Table1[[#This Row],[Account]],Table2[Account],0), 3) -> 723 | E101: =Table1[[#This Row],[P/L]]/INDEX(Table2[], MATCH(Table1[[#This Row],[Account]], Table2[Account],0),2) -> 0.17962733
A102: 45718 | B102: Monzo (Spend) | C102: 1472 | D102: =Table1[[#This Row],[Amount]]-INDEX(Table2[], MATCH(Table1[[#This Row],[Account]],Table2[Account],0), 2) + INDEX(Table2[], MATCH(Table1[[#This Row],[Account]],Table2[Account],0), 3) -> #N/A | E102: =Table1[[#This Row],[P/L]]/INDEX(Table2[], MATCH(Table1[[#This Row],[Account]], Table2[Account],0),2) -> #N/A
A103: 45718 | B103: Debit (Revolut) | C103: 20 | D103: =Table1[[#This Row],[Amount]]-INDEX(Table2[], MATCH(Table1[[#This Row],[Account]],Table2[Account],0), 2) + INDEX(Table2[], MATCH(Table1[[#This Row],[Account]],Table2[Account],0), 3) -> #N/A | E103: =Table1[[#This Row],[P/L]]/INDEX(Table2[], MATCH(Table1[[#This Row],[Account]], Table2[Account],0),2) -> #N/A
A104: 45718 | B104: Credit | C104: 0 | D104: =Table1[[#This Row],[Amount]]-INDEX(Table2[], MATCH(Table1[[#This Row],[Account]],Table2[Account],0), 2) + INDEX(Table2[], MATCH(Table1[[#This Row],[Account]],Table2[Account],0), 3) -> #N/A | E104: =Table1[[#This Row],[P/L]]/INDEX(Table2[], MATCH(Table1[[#This Row],[Account]], Table2[Account],0),2) -> #N/A
A105: 45718 | B105: Monzo (Savings) | C105: 426 | D105: =Table1[[#This Row],[Amount]]-INDEX(Table2[], MATCH(Table1[[#This Row],[Account]],Table2[Account],0), 2) + INDEX(Table2[], MATCH(Table1[[#This Row],[Account]],Table2[Account],0), 3) -> 426 | E105: =Table1[[#This Row],[P/L]]/INDEX(Table2[], MATCH(Table1[[#This Row],[Account]], Table2[Account],0),2) -> #DIV/0!
...

Sheet Montly Expenses
B2: Income
B3: Source | C3: Week | D3: Month | E3: Year | F3: As Monthly
B4: Aether | D4: 1976 | F4: 1976
B5: Other | F5: =C5*4+D5+E5/12 -> 0
E6: Total | F6: =SUM(F4:F5) -> 1976
B8: Monthly Expenditure:
B9: Category | C9: Weekly Spend | D9: Monthly Spend | E9: Yearly Spend | F9: As Monthly
B10: Rent | D10: 400 | F10: =C10*4+D10+E10/12 -> 400
B11: Groceries | C11: 40 | F11: =C11*4+D11+E11/12 -> 160
B12: Gym | D12: 35 | F12: =C12*4+D12+E12/12 -> 35
B13: Climbing | D13: 33 | F13: =C13*4+D13+E13/12 -> 33
B14: Personal care | D14: =90-D13-D12 -> 22 | F14: =C14*4+D14+E14/12 -> 22
B15: Eating out | D15: 150 | F15: =C15*4+D15+E15/12 -> 150
B16: Entertainment | D16: 150 | F16: =C16*4+D16+E16/12 -> 150
B17: Spotify | D17: 20 | F17: =C17*4+D17+E17/12 -> 20
B18: Fuel | D18: 90 | F18: =C18*4+D18+E18/12 -> 90
E19: Total | F19: =SUM(F10:F18) -> 1060
D21: =D24+D25 -> 642
B22: Monthly Expenditure (new):
B23: Category | C23: Weekly Spend | D23: Monthly Spend | E23: Yearly Spend | F23: As Monthly | G23: As Yearly
B24: Rent | D24: =950/2 -> 475 | F24: =C24*4+D24+E24/12 -> 475 | G24: =Spend_New[[#This Row],[As Monthly]]*12 -> 5700
B25: Bills | D25: =(15+50+80+189)/2 -> 167 | F25: =C25*4+D25+E25/12 -> 167 | G25: =Spend_New[[#This Row],[As Monthly]]*12 -> 2004
B26: Groceries | C26: 50 | F26: =C26*4+D26+E26/12 -> 200 | G26: =Spend_New[[#This Row],[As Monthly]]*12 -> 2400
B27: Gym | D27: 30 | F27: =C27*4+D27+E27/12 -> 30 | G27: =Spend_New[[#This Row],[As Monthly]]*12 -> 360
B28: Climbing | D28: 35 | F28: =C28*4+D28+E28/12 -> 35 | G28: =Spend_New[[#This Row],[As Monthly]]*12 -> 420
B29: Personal care | D29: 30 | F29: =C29*4+D29+E29/12 -> 30 | G29: =Spend_New[[#This Row],[As Monthly]]*12 -> 360
B30: Eating out | D30: 100 | F30: =C30*4+D30+E30/12 -> 100 | G30: =Spend_New[[#This Row],[As Monthly]]*12 -> 1200
B31: Entertainment | D31: 100 | F31: =C31*4+D31+E31/12 -> 100 | G31: =Spend_New[[#This Row],[As Monthly]]*12 -> 1200
B32: Spotify | D32: 22 | F32: =C32*4+D32+E32/12 -> 22 | G32: =Spend_New[[#This Row],[As Monthly]]*12 -> 264
B33: Fuel | D33: 90 | F33: =C33*4+D33+E33/12 -> 90 | G33: =Spend_New[[#This Row],[As Monthly]]*12 -> 1080
E34: Total | F34: =SUM(F24:F33) -> 1249 | G34: =Spend_New[[#This Row],[As Monthly]]*12 -> 14988

Sheet Other Expenditure
B1: Other Expenditure (Monthly):
B3: Reason | C3: Category | D3: Date | E3: Amount | F3: Note
B4: NYE | C4: Holiday/Fun | D4: 45627 | E4: 150
B5: Car Tax | C5: Car | D5: 45658 | E5: 385
B6: Korn Bday | C6: Gifts | D6: 45689 | E6: 15
B7: Poland | C7: Holiday/Fun | D7: 45689 | E7: 200
B8: JB Bday | C8: Holiday/Fun | D8: 45717 | E8: 170 | F8: Ticket paid
B9: My Bday | C9: Holiday/Fun | D9: 45748 | E9: 50
B10: Kimmy Stag do | C10: Holiday/Fun | D10: 45748 | E10: 200
B11: Easter Minehead | C11: Holiday/Fun | D11: 45748 | E11: 200
B12: Garmin Watch | C12: Gifts | D12: 45748 | E12: 200
B13: Watch | C13: Gifts | D13: 45778 | E13: 300 | F13: 100 paid for by mun n da
B14: Kim & Ce Wedding | C14: Holiday/Fun | D14: 45778 | E14: 800 | F14: Flights paid - accom calise/kim (not paid)
B15: Big Weekend | C15: Holiday/Fun | D15: 45778 | E15: 100
B16: Lido Fest | C16: Holiday/Fun | D16: 45809 | E16: 150
B17: Tay wedding | C17: Holiday/Fun | D17: 45809 | E17: 100
B18: Three peaks | C18: Holiday/Fun | D18: 45809 | E18: 200
B19: Copenhagen | C19: Holiday/Fun | D19: 45809 | E19: 200
B20: Harv in pool | C20: Holiday/Fun | D20: 45839 | E20: 100
B21: Oasis | C21: Holiday/Fun | D21: 45839 | E21: 250 | F21: 150 ticket, 100 spend inc. train
B22: Bongos | C22: Holiday/Fun | D22: 45870 | E22: 100
B23: Prague | C23: Holiday/Fun | D23: 45931 | E23: 500
B24: Athens Marathon & Cyprus | C24: Holiday/Fun | D24: 45962 | E24: 300 | F24: 300 flights (done) 300 spend
B25: Barry can't swim | C25: Holiday/Fun | D25: 45962 | E25: 150 | F25: accom booked
B26: Christmas | C26: Gifts | D26: 45992 | E26: 150 | F26: 50 K, 100 Fam
B27: Car Tax | C27: Car | D27: 46023 | E27: 395
B28: Korn's b day bash Poland | C28: Holiday/Fun | D28: 46054 | E28: 500 | F28: 70 flight, 180 spend
B29: Suit | C29: Weddings | D29: 46054 | E29: 150
B30: LJ Stag 1 | C30: Weddings | D30: 46082 | E30: 100 | F30: LJ Stag - painballing and Oxford
B31: LJ Stag 2 | C31: Weddings | D31: 46082 | E31: 300 | F31: LJ Stag the big one
B32: Ski hol | C32: Holiday/Fun | D32: 46082 | E32: 1200 | F32: Flights and accom paid
B33: LJ Wedding | C33: Weddings | D33: 46082 | E33: 100 | F33: Taxis/Booze
B34: Korns bday present | C34: Gifts | D34: 46113 | E34: 400 | F34: Flights and accom
B35: George & Sian - Cyprus | C35: Weddings | D35: 46143 | E35: 300 | F35: 100 flight, 200 Spend, 50 gift
B36: Poland wedding | C36: Weddings | D36: 46143 | E36: 300
B37: Car insurance | C37: Car | D37: 46143 | E37: 300 | F37: Unsure on the deets of this - insured through dad
B38: Survey for house | C38: House | D38: 46143 | E38: 300
B39: Mortgage Broker | C39: House | D39: 46143 | E39: 300
B40: Solicitor - First payment | C40: House | D40: 46143 | E40: 200 | F40: For searches
B41: Solicitor - other payments | C41: House | D41: 46204 | E41: 800 | F41: Rest of the bill
...

Sheet Calcs
A1: Calculations
A3: Income
A4: Total (monthly) | B4: ='Montly Expenses'!F6 -> 1976
A7: Monthly spend
A8: Date | B8: Monthly Expenditure | C8: Other Expenditure | D8: Total Expenditure | E8: Income | F8: Remaining Cash | G8: Cumulative Cash
A9: 45778 | B9: {=INDEX(Spend[], ROWS(Spend[]), COLUMNS(Spend[]))} -> 1060 | C9: =SUMIF(Table3[Date],Calcs!A9,Table3[Amount]) -> 1200 | D9: =SUM(B9:C9) -> 2260 | E9: =$B$4 -> 1976 | F9: =E9-D9 -> -284 | G9: =F9 -> -284
A10: 45809 | B10: {=INDEX(Spend[], ROWS(Spend[]), COLUMNS(Spend[]))} -> 1060 | C10: =SUMIF(Table3[Date],Calcs!A10,Table3[Amount]) -> 650 | D10: =SUM(B10:C10) -> 1710 | E10: =$B$4 -> 1976 | F10: =E10-D10 -> 266 | G10: =G9+F10 -> -18
A11: 45839 | B11: {=INDEX(Spend[], ROWS(Spend[]), COLUMNS(Spend[]))} -> 1060 | C11: =SUMIF(Table3[Date],Calcs!A11,Table3[Amount]) -> 350 | D11: =SUM(B11:C11) -> 1410 | E11: =$B$4 -> 1976 | F11: =E11-D11 -> 566 | G11: =G10+F11 -> 548
A12: 45870 | B12: {=INDEX(Spend[], ROWS(Spend[]), COLUMNS(Spend[]))} -> 1060 | C12: =SUMIF(Table3[Date],Calcs!A12,Table3[Amount]) -> 100 | D12: =SUM(B12:C12) -> 1160 | E12: =$B$4 -> 1976 | F12: =E12-D12 -> 816 | G12: =G11+F12 -> 1364
A13: 45901 | B13: {=INDEX(Spend[], ROWS(Spend[]), COLUMNS(Spend[]))} -> 1060 | C13: =SUMIF(Table3[Date],Calcs!A13,Table3[Amount]) -> 0 | D13: =SUM(B13:C13) -> 1060 | E13: =$B$4 -> 1976 | F13: =E13-D13 -> 916 | G13: =G12+F13 -> 2280
A14: 45931 | B14: {=INDEX(Spend_New[], ROWS(Spend_New[]), COLUMNS(Spend_New[])-1)} -> 1249 | C14: =SUMIF(Table3[Date],Calcs!A14,Table3[Amount]) -> 500 | D14: =SUM(B14:C14) -> 1749 | E14: 2178 | F14: =E14-D14 -> 429 | G14: =G13+F14 -> 2709
A15: 45962 | B15: {=INDEX(Spend_New[], ROWS(Spend_New[]), COLUMNS(Spend_New[])-1)} -> 1249 | C15: =SUMIF(Table3[Date],Calcs!A15,Table3[Amount]) -> 450 | D15: =SUM(B15:C15) -> 1699 | E15: 2178 | F15: =E15-D15 -> 479 | G15: =G14+F15 -> 3188
A16: 45992 | B16: {=INDEX(Spend_New[], ROWS(Spend_New[]), COLUMNS(Spend_New[])-1)} -> 1249 | C16: =SUMIF(Table3[Date],Calcs!A16,Table3[Amount]) -> 150 | D16: =SUM(B16:C16) -> 1399 | E16: 2178 | F16: =E16-D16 -> 779 | G16: =G15+F16 -> 3967
A17: 46023 | B17: {=INDEX(Spend_New[], ROWS(Spend_New[]), COLUMNS(Spend_New[])-1)} -> 1249 | C17: =SUMIF(Table3[Date],Calcs!A17,Table3[Amount]) -> 395 | D17: =SUM(B17:C17) -> 1644 | E17: 2178 | F17: =E17-D17 -> 534 | G17: =G16+F17 -> 4501
A18: 46054 | B18: {=INDEX(Spend_New[], ROWS(Spend_New[]), COLUMNS(Spend_New[])-1)} -> 1249 | C18: =SUMIF(Table3[Date],Calcs!A18,Table3[Amount]) -> 650 | D18: =SUM(B18:C18) -> 1899 | E18: 2178 | F18: =E18-D18 -> 279 | G18: =G17+F18 -> 4780
A19: 46082 | B19: {=INDEX(Spend_New[], ROWS(Spend_New[]), COLUMNS(Spend_New[])-1)} -> 1249 | C19: =SUMIF(Table3[Date],Calcs!A19,Table3[Amount]) -> 1700 | D19: =SUM(B19:C19) -> 2949 | E19: 2317.02 | F19: =E19-D19 -> -631.98 | G19: =G18+F19 -> 4148.02
A20: 46113 | B20: {=INDEX(Spend_New[], ROWS(Spend_New[]), COLUMNS(Spend_New[])-1)} -> 1249 | C20: =SUMIF(Table3[Date],Calcs!A20,Table3[Amount]) -> 400 | D20: =SUM(B20:C20) -> 1649 | E20: 2317.02 | F20: =E20-D20 -> 668.02 | G20: =G19+F20 -> 4816.04
A21: 46143 | B21: {=INDEX(Spend_New[], ROWS(Spend_New[]), COLUMNS(Spend_New[])-1)} -> 1249 | C21: =SUMIF(Table3[Date],Calcs!A21,Table3[Amount]) -> 1700 | D21: =SUM(B21:C21) -> 2949 | E21: 2317.02 | F21: =E21-D21 -> -631.98 | G21: =G20+F21 -> 4184.06
A22: 46174 | B22: {=INDEX(Spend_New[], ROWS(Spend_New[]), COLUMNS(Spend_New[])-1)} -> 1249 | C22: =SUMIF(Table3[Date],Calcs!A22,Table3[Amount]) -> 0 | D22: =SUM(B22:C22) -> 1249 | E22: 2317.02 | F22: =E22-D22 -> 1068.02 | G22: =G21+F22 -> 5252.08
A23: 46204 | B23: {=INDEX(Spend_New[], ROWS(Spend_New[]), COLUMNS(Spend_New[])-1)} -> 1249 | C23: =SUMIF(Table3[Date],Calcs!A23,Table3[Amount]) -> 800 | D23: =SUM(B23:C23) -> 2049 | E23: 2317.02 | F23: =E23-D23 -> 268.02 | G23: =G22+F23 -> 5520.1
A24: 46235 | B24: {=INDEX(Spend_New[], ROWS(Spend_New[]), COLUMNS(Spend_New[])-1)} -> 1249 | C24: =SUMIF(Table3[Date],Calcs!A24,Table3[Amount]) -> 0 | D24: =SUM(B24:C24) -> 1249 | E24: 2317.02 | F24: =E24-D24 -> 1068.02 | G24: =G23+F24 -> 6588.12
A25: 46266 | B25: {=INDEX(Spend_New[], ROWS(Spend_New[]), COLUMNS(Spend_New[])-1)} -> 1249 | C25: =SUMIF(Table3[Date],Calcs!A25,Table3[Amount]) -> 450 | D25: =SUM(B25:C25) -> 1699 | E25: 2317.02 | F25: =E25-D25 -> 618.02 | G25: =G24+F25 -> 7206.14
... A29: 46388 | B29: {=INDEX(Spend_New[], ROWS(Spend_New[]), COLUMNS(Spend_New[])-1)} -> 1249 | C29: =SUMIF(Table3[Date],Calcs!A29,Table3[Amount]) -> 0 | D29: =SUM(B29:C29) -> 1249 | E29: 2318.02 | F29: =E29-D29 -> 1069.02 | G29: =G28+F29 -> 11479.22

Sheet Projections
A1: Projections
A3: Date of Projection: 01/07/25
A4: Date | B4: Total Expenditure | C4: Remaining cash | D4: Projected Worth | E4: Actual Worth
A5: 45839 | B5: =VLOOKUP(Projections!A5,Calcs!$A:$G,4,FALSE) -> 1410 | C5: =VLOOKUP(Projections!A5,Calcs!$A:$G,6,FALSE) -> 566 | D5: =GETPIVOTDATA("Amount",'Net Worth Dashboard'!$A$42,"Date",DATE(2025,7,1)) -> 24885 | E5: =GETPIVOTDATA("Amount",'Net Worth Dashboard'!$A$42,"Date",DATE(2025,7,1)) -> 24885
A6: 45870 | B6: =VLOOKUP(Projections!A6,Calcs!$A:$G,4,FALSE) -> 1160 | C6: =VLOOKUP(Projections!A6,Calcs!$A:$G,6,FALSE) -> 816 | D6: =D5+C6 -> 25701 | E6: =GETPIVOTDATA("Amount",'Net Worth Input'!$A$123,"Date",DATE(2025,8,3)) -> 25952
A7: 45901 | B7: =VLOOKUP(Projections!A7,Calcs!$A:$G,4,FALSE) -> 1060 | C7: =VLOOKUP(Projections!A7,Calcs!$A:$G,6,FALSE) -> 916 | D7: =D6+C7 -> 26617 | E7: =(E6+E8)/2 -> 26977.505
A8: 45931 | B8: =VLOOKUP(Projections!A8,Calcs!$A:$G,4,FALSE) -> 1749 | C8: =VLOOKUP(Projections!A8,Calcs!$A:$G,6,FALSE) -> 429 | D8: =D7+C8 -> 27046 | E8: =GETPIVOTDATA("Amount",'Net Worth Input'!$A$123,"Date",DATE(2025,11,1)) -> 28003.01
A9: 45962 | B9: =VLOOKUP(Projections!A9,Calcs!$A:$G,4,FALSE) -> 1699 | C9: =VLOOKUP(Projections!A9,Calcs!$A:$G,6,FALSE) -> 479 | D9: =D8+C9 -> 27525 | E9: =GETPIVOTDATA("Amount",'Net Worth Input'!$A$123,"Date",DATE(2025,12,9)) -> 27601.05
A10: 45992 | B10: =VLOOKUP(Projections!A10,Calcs!$A:$G,4,FALSE) -> 1399 | C10: =VLOOKUP(Projections!A10,Calcs!$A:$G,6,FALSE) -> 779 | D10: =D9+C10 -> 28304 | E10: =GETPIVOTDATA("Amount",'Net Worth Input'!$A$123,"Date",DATE(2025,12,30)) -> 28948
A11: 46023 | B11: =VLOOKUP(Projections!A11,Calcs!$A:$G,4,FALSE) -> 1644 | C11: =VLOOKUP(Projections!A11,Calcs!$A:$G,6,FALSE) -> 534 | D11: =D10+C11 -> 28838 | E11: =GETPIVOTDATA("Amount",'Net Worth Input'!$A$123,"Date",DATE(2026,2,10)) -> 26608
A12: 46054 | B12: =VLOOKUP(Projections!A12,Calcs!$A:$G,4,FALSE) -> 1899 | C12: =VLOOKUP(Projections!A12,Calcs!$A:$G,6,FALSE) -> 279 | D12: =D11+C12 -> 29117 | E12: =(E11+E13)/2 -> 26248.115
A13: 46082 | B13: =VLOOKUP(Projections!A13,Calcs!$A:$G,4,FALSE) -> 2949 | C13: =VLOOKUP(Projections!A13,Calcs!$A:$G,6,FALSE) -> -631.98 | D13: =D12+C13 -> 28485.02 | E13: =GETPIVOTDATA("Amount",'Net Worth Input'!$A$123,"Date",DATE(2026,4,6)) -> 25888.23
A14: 46113 | B14: =VLOOKUP(Projections!A14,Calcs!$A:$G,4,FALSE) -> 1649 | C14: =VLOOKUP(Projections!A14,Calcs!$A:$G,6,FALSE) -> 668.02 | D14: =D13+C14 -> 29153.04 | E14: =GETPIVOTDATA("Amount",'Net Worth Input'!$A$123,"Date",DATE(2026,5,15)) -> 26766
A15: 46143 | B15: =VLOOKUP(Projections!A15,Calcs!$A:$G,4,FALSE) -> 2949 | C15: =VLOOKUP(Projections!A15,Calcs!$A:$G,6,FALSE) -> -631.98 | D15: =D14+C15 -> 28521.06 | E15: =GETPIVOTDATA("Amount",'Net Worth Input'!$A$123,"Date",DATE(2026,6,4))-15000 -> 27093
A16: 46174 | B16: =VLOOKUP(Projections!A16,Calcs!$A:$G,4,FALSE) -> 1249 | C16: =VLOOKUP(Projections!A16,Calcs!$A:$G,6,FALSE) -> 1068.02 | D16: =D15+C16 -> 29589.08
A17: 46204 | B17: =VLOOKUP(Projections!A17,Calcs!$A:$G,4,FALSE) -> 2049 | C17: =VLOOKUP(Projections!A17,Calcs!$A:$G,6,FALSE) -> 268.02 | D17: =D16+C17 -> 29857.1
A18: 46235 | B18: =VLOOKUP(Projections!A18,Calcs!$A:$G,4,FALSE) -> 1249 | C18: =VLOOKUP(Projections!A18,Calcs!$A:$G,6,FALSE) -> 1068.02 | D18: =D17+C18 -> 30925.12
A19: 46266 | B19: =VLOOKUP(Projections!A19,Calcs!$A:$G,4,FALSE) -> 1699 | C19: =VLOOKUP(Projections!A19,Calcs!$A:$G,6,FALSE) -> 618.02 | D19: =D18+C19 -> 31543.14
A20: 46296 | B20: =VLOOKUP(Projections!A20,Calcs!$A:$G,4,FALSE) -> 1249 | C20: =VLOOKUP(Projections!A20,Calcs!$A:$G,6,FALSE) -> 1068.02 | D20: =D19+C20 -> 32611.16
A21: 46327 | B21: =VLOOKUP(Projections!A21,Calcs!$A:$G,4,FALSE) -> 1249 | C21: =VLOOKUP(Projections!A21,Calcs!$A:$G,6,FALSE) -> 1068.02 | D21: =D20+C21 -> 33679.18
A22: 46357 | B22: =VLOOKUP(Projections!A22,Calcs!$A:$G,4,FALSE) -> 1249 | C22: =VLOOKUP(Projections!A22,Calcs!$A:$G,6,FALSE) -> 1068.02 | D22: =D21+C22 -> 34747.2
A23: 46388 | B23: =VLOOKUP(Projections!A23,Calcs!$A:$G,4,FALSE) -> 1249 | C23: =VLOOKUP(Projections!A23,Calcs!$A:$G,6,FALSE) -> 1069.02 | D23: =D22+C23 -> 35816.22

Sheet WEEKLY
B3: WC | C3: 45544 | D3: =C3+7 -> 45551 | E3: =D3+7 -> 45558 | F3: =E3+7 -> 45565 | G3: =F3+7 -> 45572 | H3: =G3+7 -> 45579 | I3: =H3+7 -> 45586 | J3: =I3+7 -> 45593 | K3: =J3+7 -> 45600 | ... AY3: =AX3+7 -> 45880
A4: Income: | B4: Aether | F4: 1700 | J4: 1700 | N4: 1700 | W4: 1900 | Z4: 1900 | AE4: 1900 | AJ4: 1900 | AM4: 1900
B5: Other
B6: Total income | C6: =SUM(C4:C5) -> 0 | D6: =SUM(D4:D5) -> 0 | E6: =SUM(E4:E5) -> 0 | F6: =SUM(F4:F5) -> 1700 | G6: =SUM(G4:G5) -> 0 | H6: =SUM(H4:H5) -> 0 | I6: =SUM(I4:I5) -> 0 | J6: =SUM(J4:J5) -> 1700 | ... AY6: =SUM(AY4:AY5) -> 0
A7: Expenditure:
B8: Rent | F8: 400 | J8: 400 | N8: 400 | S8: 400 | W8: 400 | AA8: 400 | AF8: 400 | AJ8: 400 | AN8: 400
B9: Food | C9: 20 | D9: 20 | E9: 20 | F9: 20 | G9: 20 | H9: 20 | I9: 20 | J9: 20 | K9: 20 | L9: 20 | M9: 20 | N9: 20 | O9: 20 | P9: 20 | Q9: 20 | R9: 20 | S9: 20 | T9: 20 | U9: 20 | V9: 20 | W9: 20 | X9: 20 | Y9: 20 | Z9: 20 | AA9: 20 | AB9: 20 | AC9: 20 | AD9: 20 | AE9: 20 | AF9: 20 | AG9: 20 | AH9: 20 | AI9: 20 | AJ9: 20 | AK9: 20 | AL9: 20 | AM9: 20 | AN9: 20 | AO9: 20 | AP9: 20 | AQ9: 20 | AR9: 20 | AS9: 20 | AT9: 20 | AU9: 20 | AV9: 20 | AW9: 20 | AX9: 20 | AY9: 20
B10: Gym + Active | F10: 65 | J10: 65 | N10: 65 | S10: 65 | W10: 65 | AA10: 65 | AF10: 65 | AJ10: 65 | AN10: 65 | AS10: 65
B11: Spotify | F11: 20 | J11: 20 | N11: 20 | S11: 20 | W11: 20 | AA11: 20 | AF11: 20 | AJ11: 20 | AN11: 20 | AS11: 20
B12: Weekly spend | C12: 50 | D12: 50 | E12: 50 | F12: 50 | G12: 50 | H12: 50 | I12: 50 | J12: 50 | K12: 50 | L12: 50 | M12: 50 | N12: 50 | O12: 50 | P12: 50 | Q12: 50 | R12: 50 | S12: 50 | T12: 50 | U12: 50 | V12: 50 | W12: 50 | X12: 50 | Y12: 50 | Z12: 50 | AA12: 50 | AB12: 50 | AC12: 50 | AD12: 50 | AE12: 50 | AF12: 50 | AG12: 50 | AH12: 50 | AI12: 50 | AJ12: 50 | AK12: 50 | AL12: 50 | AM12: 50 | AN12: 50 | AO12: 50 | AP12: 50 | AQ12: 50 | AR12: 50 | AS12: 50 | AT12: 50 | AU12: 50 | AV12: 50 | AW12: 50 | AX12: 50 | AY12: 50
B13: Misc spend | D13: 500 | F13: 200 | S13: 150 | V13: 100 | W13: 200 | AC13: 150
B14: Savings | S14: 400 | W14: 400 | AA14: 400 | AF14: 400 | AJ14: 400
B15: Investment
B16: Total outgoing | C16: =SUM(C8:C15) -> 70 | D16: =SUM(D8:D15) -> 570 | E16: =SUM(E8:E15) -> 70 | F16: =SUM(F8:F15) -> 755 | G16: =SUM(G8:G15) -> 70 | H16: =SUM(H8:H15) -> 70 | I16: =SUM(I8:I15) -> 70 | J16: =SUM(J8:J15) -> 555 | ... AY16: =SUM(AY8:AY15) -> 70
B18: End of Week Total | C18: 6115 | D18: =C18+D6-D16 -> 5545 | E18: =D18+E6-E16 -> 5475 | F18: =E18+F6-F16 -> 6420 | G18: =F18+G6-G16 -> 6350 | H18: =G18+H6-H16 -> 6280 | I18: =H18+I6-I16 -> 6210 | J18: =I18+J6-J16 -> 7355 | K18: =J18+K6-K16 -> 7285 | ... Q18: =P18+Q6-Q16 -> 8080 | R18: 5444 | S18: =R18+S6-S16 -> 4339 | T18: =S18+T6-T16 -> 4269 | U18: =T18+U6-U16 -> 4199 | V18: =U18+V6-V16 -> 4029 | W18: =V18+W6-W16 -> 4774 | X18: =W18+X6-X16 -> 4704 | Y18: =X18+Y6-Y16 -> 4634 | Z18: =Y18+Z6-Z16 -> 6464 | ... AY18: =AX18+AY6-AY16 -> 7039
A21: OWED
A22: Adam | B22: -300
A29: Total | B29: =SUM(B22:B28) -> -300

Sheet PENSION
A1: Legal & General
A2: THE ABBOTT RETIREMENT SAVER (2015)
A3: Account number | B3: 2724065401
A4: Date | B4: 45306
A5: Invested | B5: 12040.62
A6: Balance | B6: 13659.96
A7: %G/L | B7: =((B6-B5)/B5) -> 0.13448975
A10: Cushon
A11: Aether Pension Pot
A12: Date | B12: 45547
A13: Me | B13: 108
A14: Aether | B14: 173
A15: Investment/Monthly | B15: =SUM(B13:B14) -> 281
A16: Balance | B16: 2056
A17: %G/L | B17: =((B16-B15)/B15) -> 6.316726

Sheet CRYPTO
A2: Price
B3: -0.5 | C3: -0.4 | D3: -0.3 | E3: -0.2 | F3: -0.1 | G3: Current Price | H3: 0.1 | I3: 20% | J3: 30% | K3: 0.4 | L3: 0.5 | M3: 0.6 | N3: 0.7 | O3: 0.8 | P3: 0.9 | Q3: 1
A4: BTC | B4: =$G4*(1+B$3) -> 21000 | C4: =$G4*(1+C$3) -> 25200 | D4: =$G4*(1+D$3) -> 29400 | E4: =$G4*(1+E$3) -> 33600 | F4: =$G4*(1+F$3) -> 37800 | G4: 42000 | H4: =$G4*(1+H$3) -> 46200 | I4: =$G4*(1+I$3) -> 50400 | J4: =$G4*(1+J$3) -> 54600 | K4: =$G4*(1+K$3) -> 58800 | L4: =$G4*(1+L$3) -> 63000 | M4: =$G4*(1+M$3) -> 67200 | N4: =$G4*(1+N$3) -> 71400 | O4: =$G4*(1+O$3) -> 75600 | ... Q4: =$G4*(1+Q$3) -> 84000
A5: ETH | B5: =$G5*(1+B$3) -> 1100 | C5: =$G5*(1+C$3) -> 1320 | D5: =$G5*(1+D$3) -> 1540 | E5: =$G5*(1+E$3) -> 1760 | F5: =$G5*(1+F$3) -> 1980 | G5: 2200 | H5: =$G5*(1+H$3) -> 2420 | I5: =$G5*(1+I$3) -> 2640 | J5: =$G5*(1+J$3) -> 2860 | K5: =$G5*(1+K$3) -> 3080 | L5: =$G5*(1+L$3) -> 3300 | M5: =$G5*(1+M$3) -> 3520 | N5: =$G5*(1+N$3) -> 3740 | O5: =$G5*(1+O$3) -> 3960 | ... Q5: =$G5*(1+Q$3) -> 4400
A8: Holdings
B9: Amount, C | C9: Amount, F | D9: Avrg Buy
A10: BTC | B10: 0.04383117 | C10: =B10*G4 -> 1840.9091 | D10: 44000
A11: ETH | B11: 0.4 | C11: 880 | D11: 2080
A13: Strat
A15: BTC
B16: -0.5 | C16: -0.4 | D16: -0.3 | E16: -0.2 | F16: -0.1 | G16: Current | H16: 0.1 | I16: 20% | J16: 30% | K16: 0.4 | L16: 0.5 | M16: 0.6 | N16: 0.7 | O16: 0.8 | P16: 0.9 | Q16: 1
A17: Price Points | B17: =B4 -> 21000 | C17: =C4 -> 25200 | D17: =D4 -> 29400 | E17: =E4 -> 33600 | F17: =F4 -> 37800 | G17: =G4 -> 42000 | H17: =H4 -> 46200 | I17: =I4 -> 50400 | ... Q17: =Q4 -> 84000
A18: Holdings | B18: HODL | G18: =C10 -> 1840.9091 | H18: =$G18*1.1 -> 2025.0001 | I18: =(H18-H19)*1.1 -> 1897.5001 | J18: =(I18-I19)*1.1 -> 1647.2501 | K18: =(J18-J19)*1.1 -> 1371.9751 | L18: =(K18-K19)*1.1 -> 1399.1726 | M18: =(L18-L19)*1.1 -> 1429.0898 | N18: =(M18-N19)*1.1 -> 1351.9988 | O18: =(N18-O19)*1.1 -> 1267.1987 | P18: =(O18-P19)*1.1 -> 1173.9186 | Q18: =(P18-Q19)*1.1 -> 1071.3104
A19: Sell ($) | H19: 300 | I19: 400 | J19: 400 | K19: 100 | L19: 100 | M19: 200 | N19: 200 | O19: 200 | P19: 200 | Q19: 200
A20: Sell (BTC) | H20: =(H19/H17) -> 0.0064935065 | I20: =(I19/I17) -> 0.0079365079 | J20: =(J19/J17) -> 0.0073260073 | K20: =(K19/K17) -> 0.0017006803 | L20: =(L19/L17) -> 0.0015873016 | M20: =(M19/M17) -> 0.0029761905 | N20: =(N19/N17) -> 0.0028011204 | O20: =(O19/O17) -> 0.0026455026 | ... Q20: =(Q19/Q17) -> 0.0023809524
A21: Binance Wallet (BTC) | G21: 0.025044004 | H21: =G21-H20 -> 0.018550497 | I21: =H21-I20 -> 0.010613989 | J21: =I21-J20 -> 0.0032879819 | K21: =J21-K20 -> 0.0015873016 | L21: =K21-L20 -> -4.9482987e-16 | M21: =L21-M20 -> -0.0029761905 | N21: =M21-N20 -> -0.0057773109 | O21: =N21-O20 -> -0.0084228136 | ... Q21: =P21-Q20 -> -0.013310032
A22: In Bank ($) | H22: =G22+H19 -> 300 | I22: =H22+I19 -> 700 | J22: =I22+J19 -> 1100 | K22: =J22+K19 -> 1200 | L22: =K22+L19 -> 1300 | M22: =L22+N19 -> 1500 | N22: =M22+O19 -> 1700 | O22: =N22+P19 -> 1900 | P22: =O22+Q19 -> 2100 | Q22: =P22+Q19 -> 2300
A27: ETH
B28: -0.5 | C28: -0.4 | D28: -0.3 | E28: -0.2 | F28: -0.1 | G28: Current | H28: 0.1 | I28: 20% | J28: 30% | K28: 0.4 | L28: 0.5 | M28: 0.6 | N28: 0.7 | O28: 0.8 | P28: 0.9 | Q28: 1
A29: Price Points | B29: =B5 -> 1100 | C29: =C5 -> 1320 | D29: =D5 -> 1540 | E29: =E5 -> 1760 | F29: =F5 -> 1980 | G29: =G5 -> 2200 | H29: =H5 -> 2420 | I29: =I5 -> 2640 | ... Q29: =Q5 -> 4400
A30: Holdings | B30: HODL | G30: 880 | H30: =$G30*1.1 -> 968 | I30: =(H30-H31)*1.1 -> 1064.8 | J30: =(I30-I31)*1.1 -> 1061.28 | K30: =(J30-J31)*1.1 -> 1057.408 | L30: =(K30-K31)*1.1 -> 1053.1488 | M30: =(L30-L31)*1.1 -> 1048.4637 | N30: =(M30-M31)*1.1 -> 1043.31 | O30: =(N30-N31)*1.1 -> 1037.6411 | P30: =(O30-O31)*1.1 -> 1031.4052 | Q30: =(P30-P31)*1.1 -> 1024.5457
A31: Sell ($) | G31: 0 | H31: 0 | I31: 100 | J31: 100 | K31: 100 | L31: 100 | M31: 100 | N31: 100 | O31: 100 | P31: 100 | Q31: 100
A32: Sell (ETH) | H32: =(H31/H29) -> 0 | I32: =(I31/I29) -> 0.037878788 | J32: =(J31/J29) -> 0.034965035 | K32: =(K31/K29) -> 0.032467532 | L32: =(L31/L29) -> 0.03030303 | M32: =(M31/M29) -> 0.028409091 | N32: =(N31/N29) -> 0.026737968 | O32: =(O31/O29) -> 0.025252525 | ... Q32: =(Q31/Q29) -> 0.022727273
A33: Binance Wallet (ETH) | G33: 0.13561439 | H33: =G33-H32 -> 0.13561439 | I33: =H33-I32 -> 0.097735598 | J33: =I33-J32 -> 0.062770563 | K33: =J33-K32 -> 0.03030303 | L33: =K33-L32 -> 0 | M33: =L33-M32 -> -0.028409091 | N33: =M33-N32 -> -0.055147059 | O33: =N33-O32 -> -0.080399584 | ... Q33: =P33-Q32 -> -0.1270503
A34: In Bank ($) | H34: =G34+H31 -> 0 | I34: =H34+I31 -> 100 | J34: =I34+J31 -> 200 | K34: =J34+K31 -> 300 | L34: =K34+L31 -> 400 | M34: =L34+M31 -> 500 | N34: =M34+N31 -> 600 | O34: =N34+O31 -> 700 | ... Q34: =P34+Q31 -> 900
A39: Alts: | B39: Sell 75% at BTC market dom of 40% or:
B40: Holdings | C40: Value (13/03/24)
A41: ADA | B41: 695 | C41: 536
A42: CKB | B42: 14011 | C42: 326
A43: ROSE | B43: 1720 | C43: 303
A44: ALGO | B44: 728 | C44: 230
A45: ERG | B45: 72 | C45: 164
A46: CRO | B46: 726 | C46: 118
C47: =SUM(C41:C46) -> 1677

Sheet GOALS
B2: Goal | C2: Cost | D2: Timeframe (months) | E2: Monthly Saving | F2: Comment
B3: House | C3: 5000 | D3: 39 | E3: =C3/D3 -> 128.20513 | F3: Assuming 200k house @ 15% deposit
B4: Holidays | C4: 2000 | D4: 12 | E4: =C4/D4 -> 166.66667
B5: Car | C5: 6000 | D5: =12*5 -> 60 | E5: =C5/D5 -> 100
B6: Van | C6: 2000 | D6: =12*5 -> 60 | E6: =C6/D6 -> 33.333333
B7: Backpacking Trip | C7: 5000 | D7: =12*3 -> 36 | E7: =C7/D7 -> 138.88889 | F7: 3 month trip to South America
E8: =SUM(E3:E7) -> 567.09402

Sheet Lists
B2: Accounts
B3: Nutmeg (LISA)
B4: S&S ISA
B5: Crypto
B6: Credit
B7: Monzo (Spend)
B8: Monzo (Savings)
B9: Debit (Revolut)
B10: Chase
B15: OtherExpenditure
B16: Holiday/Fun
B17: Gifts
... B40: Car
